<?xml version="1.0"?>
<robot name="sark"
       xmlns:sensor="http://playerstage.sourceforge.net/gazebo/xmlschema/#sensor"
       xmlns:controller="http://playerstage.sourceforge.net/gazebo/xmlschema/#controller"
       xmlns:xacro="http://ros.org/wiki/fixme"
       xmlns:interface="http://playerstage.sourceforge.net/gazebo/xmlschema/#interface">

  <property name="M_PI" value="3.14159"/>

  <link name="world">
    <!--<inertial>
      <mass value="0.05" />
      <origin xyz="-0.0 0.0 -10.0" />
      <inertia ixx="1.0" ixy="0.0" ixz="0.0"
               iyy="1.0" iyz="0.0"
               izz="1.0" />
    </inertial>-->

    <collision>
      <origin xyz="0 0 0.15" rpy="0 0 0" />
      <geometry>
        <box size="0.4 0.4 0.3" />
      </geometry>
    </collision>
  </link>

  <joint name="base_joint_s" type="fixed">
    <origin rpy="0 0 0.0" xyz="0.0 0.0 0.0"/>
    <parent link="world"/>
    <child link="sark_base"/>
  </joint>

  <link name="sark_base">
    <inertial>
      <mass value="0" />
      <origin xyz="-0.0 0.0 0.0" />
      <inertia ixx="1.0" ixy="0.0" ixz="0.0"
               iyy="1.0" iyz="0.0"
               izz="1.0" />
    </inertial>

    <collision>
      <origin xyz="0 0 0.5" rpy="0 0 0" />
      <geometry>
        <box size="0.2 0.4 1.0" />
      </geometry>
    </collision>
    <visual>
      <origin xyz="0 0 0.5" />
      <geometry>
        <box size="0.1 0.4 1.07" />
      </geometry>
      <material name="gray">
      <color rgba=".2 .2 .2 1" />
    </material>
    </visual>
    <visual>
      <origin rpy="0 1.57 0" xyz="0.09 0.0 0.90"/>
      <geometry>
         <cylinder radius="0.06" length="0.12"/>
      </geometry>
      <material name="gray">
      <color rgba=".2 .2 .2 1" />
    </material>
    </visual>
  </link>

  <joint name="SarkofagJoint" type="revolute">
    <origin rpy="-1.57 0 0" xyz="0.0 0.0 0.90"/>
    <axis xyz="1 0 0"/>
    <limit lower="-2.96705973" upper="2.96705973" effort="10.0" velocity="10.0" />
    <parent link="sark_base"/>
    <child link="sark_1"/>
  </joint>

  <link name="sark_1">
    <inertial>
      <mass value="0.1"/>
      <origin xyz="0.0 0.0 0.0"/>
      <inertia ixx="0.1" ixy="0" ixz="0" iyy="0.1" iyz="0" izz="0.1"/>
    </inertial>
    <visual>
      <origin rpy="-1.57 0 0.0" xyz="0.18 0.0 0.2"/>
      <geometry>
        <box size="0.02 0.8 0.04" />
      </geometry>
    </visual>
    <visual>
      <origin rpy="0 1.57 0" xyz="0.18 0.0 0.0"/>
      <geometry>
         <cylinder radius="0.06" length="0.06"/>
      </geometry>
    </visual>
    <collision>
      <origin rpy="-1.57 0 0.0" xyz="0.18 0 0.2"/>
      <geometry>
        <box size="0.02 0.8 0.04" />
      </geometry>
    </collision>
  </link>

  
</robot>
